# 10.错误、调试和测试

## 10.1错误处理

- `try...catch`机制

```python
try:
    print('try...')
    r = 10 / 0
    print('result:', r)
except ZeroDivisionError as e:
    print('except:', e)
else:
    print('no error!')		#如果没有错误发生
finally:
    print('finally...')
print('END')
```

- 所有的错误类型都继承自`BaseException`

- **调用栈**：如果错误没有被捕获，它就会一直往上抛，最后被Python解释器捕获，打印一个错误信息，然后程序退出

- **记录错误**：`logging`模块，还可以把错误日志记录到文件里方便排查

```python
# err_logging.py

import logging

def foo(s):
    return 10 / int(s)
def bar(s):
    return foo(s) * 2
def main():
    try:
        bar('0')
    except Exception as e:
        logging.exception(e)
main()
print('END')
```

- **抛出错误**：`raise`（如果不带参数就抛出原错误，还可以把一个错误转为另一种类型）

```python
def foo(s):
    n = int(s)
    if n==0:
        raise ValueError('invalid value: %s' % s)
    return 10 / n

def bar():
    try:
        foo('0')
    except ValueError as e:
        print('ValueError!')
        raise

bar()
```



## 10.2调试

- **print**()调试
- **assert**()（可以用<u>python -O err.py</u>关闭）

```python
def foo(s):
    n = int(s)
    assert n != 0, 'n is zero!'	# 若条件不满足，就抛出后面错误
    return 10 / n

def main():
    foo('0')
```

- 



## 10.3单元测试

## 10.4文档测试